package com.example.disampleapp.questions

import com.example.disampleapp.networking.StackoverflowApi



import kotlinx.coroutines.CancellationException
import kotlinx.coroutines.Dispatchers
import kotlinx.coroutines.withContext

class FetchQuestionDetailsUseCase(private val stackoverflowApi: StackoverflowApi) {

    sealed class Result {
        class Success(val question: QuestionWithBody) : Result()
        object Failure: Result()
    }

    suspend fun fetchQuestion(questionId: String): Result {
        return withContext(Dispatchers.IO) {
            try {
                val response = stackoverflowApi.questionDetails(questionId)
                if (response.isSuccessful && response.body() != null) {
                    return@withContext Result.Success(response.body()!!.question)
                } else {
                    return@withContext Result.Failure
                }
            } catch (t: Throwable) {
                if (t !is CancellationException) {
                    return@withContext Result.Failure
                } else {
                    throw t
                }
            }
        }
    }


}